<?xml version="1.0"?>
<robot xmlns:xacro="http://www.ros.org/wiki/xacro">
    <xacro:include filename="inertial_macros.xacro"/>

    <!-- RViz colors -->
    <material name="white">
        <color rgba="1 1 1 1"/>
    </material>

    <material name="orange">
        <color rgba="1 0.3 0.1 1"/>
    </material>

    <material name="blue">
        <color rgba="0.2 0.2 1 1"/>
    </material>

    <material name="black">
        <color rgba="0 0 0 1"/>
    </material>

    <!-- Base link -->
    <link name="base_link"></link>

    <!-- Chassis -->
    <joint name="chassis_joint" type="fixed">
        <parent link="base_link"/>
        <child link="chassis"/>
        <origin xyz="-0.3 0 0"/>
    </joint>
    <link name="chassis">
        <visual>
            <origin xyz="0.2 0 0.125"/>
            <geometry>
                <box size="0.4 0.4 0.25"/>
            </geometry>
            <material name="white"/>
        </visual>
        <collision>
            <origin xyz="0.2 0 0.125"/>
            <geometry>
                <box size="0.4 0.4 0.25"/>
            </geometry>
        </collision>
        <xacro:inertial_box mass="1.0" x="0.4" y="0.4" z="0.25">
            <origin xyz="0.2 0 0.125" rpy="0 0 0"/>
        </xacro:inertial_box>
    </link>
    <gazebo reference="chassis">
        <material>
            <ambient>1 1 1 1</ambient>
            <diffuse>1 1 1 1</diffuse>
            <specular>0.5 0.5 0.5 1</specular>
        </material>
    </gazebo>

    <!-- Left wheel -->
    <joint name="left_wheel_joint" type="continuous">
        <parent link="base_link"/>
        <child link="left_wheel"/>
        <origin xyz="0 0.175 0" rpy="-${pi/2} 0 0"/>
        <axis xyz="0 0 -1.5"/>
    </joint>
    <link name="left_wheel">
        <visual>
            <geometry>
                <cylinder radius="0.05" length="0.03"/>
            </geometry>
            <material name="blue"/>
        </visual>
        <collision>
            <geometry>
                <cylinder radius="0.05" length="0.03"/>
            </geometry>
        </collision>
        <xacro:inertial_cylinder mass="0.5" length="0.03" radius="0.05">
            <origin xyz="0 0 0" rpy="0 0 0"/>
        </xacro:inertial_cylinder>
    </link>
    <gazebo reference="left_wheel">
        <material>
            <ambient>0.2 0.2 1 1</ambient>
            <diffuse>0.2 0.2 1 1</diffuse>
            <specular>0.5 0.5 0.5 1</specular>
        </material>
    </gazebo>

    <!-- Right wheel -->
    <joint name="right_wheel_joint" type="continuous">
        <parent link="base_link"/>
        <child link="right_wheel"/>
        <origin xyz="0 -0.175 0" rpy="${pi/2} 0 0"/>
        <axis xyz="0 0 -1.5"/>
    </joint>
    <link name="right_wheel">
        <visual>
            <geometry>
                <cylinder radius="0.05" length="0.03"/>
            </geometry>
            <material name="blue"/>
        </visual>
        <collision>
            <geometry>
                <cylinder radius="0.05" length="0.03"/>
            </geometry>
        </collision>
        <xacro:inertial_cylinder mass="0.5" length="0.03" radius="0.05">
            <origin xyz="0 0 0" rpy="0 0 0"/>
        </xacro:inertial_cylinder>
    </link>
    <gazebo reference="right_wheel">
        <material>
            <ambient>0.2 0.2 1 1</ambient>
            <diffuse>0.2 0.2 1 1</diffuse>
            <specular>0.5 0.5 0.5 1</specular>
        </material>
    </gazebo>

    <!-- Caster wheel -->
    <joint name="caster_wheel_joint" type="fixed">
        <parent link="chassis"/>
        <child link="caster_wheel"/>
        <origin xyz="0.15 0 0"/>
    </joint>
    <link name="caster_wheel">
        <visual>
            <geometry>
                <sphere radius="0.05"/>
            </geometry>
            <material name="orange"/>
        </visual>
        <collision>
            <geometry>
                <sphere radius="0.05"/>
            </geometry>
        </collision>
        <xacro:inertial_sphere mass="0.2" radius="0.05">
            <origin xyz="0 0 0" rpy="0 0 0"/>
        </xacro:inertial_sphere>
    </link>
    <gazebo reference="caster_wheel">
        <material>
            <ambient>1 0.3 0.1 1</ambient>
            <diffuse>1 0.3 0.1 1</diffuse>
            <specular>0.5 0.5 0.5 1</specular>
        </material>
        <mu1 value="0.001"/>
        <mu2 value="0.001"/>
    </gazebo>

</robot>
