<?xml version="1.0"?>
<robot xmlns:xacro="http://www.ros.org/wiki/xacro" >
    <xacro:include filename="inertial_macros.xacro"/>
    <material name="white">
        <color rgba="1 1 1 1 "/>
    </material>

    <material name="orange">
        <color rgba="1 0.3 0.1 1"/>
    </material>

    <material name="blue">
        <color rgba="0.2 0.2 1 1"/>
    </material>

    <material name="black">
        <color rgba="0 0 0 1"/>
    </material>
    <link name="base_link">
    </link>
    <!--Chassis Link-->
    <joint name ="chassis_joint" type="fixed">
        <parent link="base_link"/>
        <child link="chassis"/>
        <origin xyz ="-0.3 0 0"/>
    </joint>
    <link name = "chassis">
        <visual>
            <origin xyz="0.2 0 0.125"/>
            
            <geometry>
                <box size="0.4 0.4 .25"/>
            </geometry>
            <material name="white"/>
        </visual>
        <collision>
            <origin xyz="0.2 0 0.125"/>
            
            <geometry>
                <box size="0.4 0.4 .25"/>
            </geometry>  
        </collision>
    </link>
    <!-- Left Wheel Link-->
    <joint name="left_wheel_joint" type="continuous">
        <parent link="base_link"/>
        <child link="left_wheel"/>
        <origin xyz ="0 0.175 0" rpy="-${pi/2} 0 0"/>
        <axis xyz="0 0 -1.5"/>
    </joint>
    <link name="left_wheel">
        <visual>
            <geometry>
                <cylinder radius="0.05" length="0.03" />
            </geometry>
            <material name="blue"/>
        </visual>

        <collision>
            <geometry>
                <cylinder radius="0.05" length="0.03" />
            </geometry>
        </collision>
    </link>
    <!--Right Wheel Link-->
    <joint name="right_wheel_joint" type="continuous">
        <parent link="base_link"/>
        <child link="right_wheel"/>
        <origin xyz ="0 -0.175 0" rpy="${pi/2} 0 0"/>
        <axis xyz="0 0 -1.5"/>
    </joint>
    <link name="right_wheel">
        <visual>
            <geometry>
                <cylinder radius="0.05" length="0.03"/>
            </geometry>
            <material name="blue"/>
        </visual>
        <collision>
            <geometry>
                <cylinder radius="0.05" length="0.03" />
            </geometry>
        </collision>
    </link>
    <!--Caster Wheel Link-->
    <joint name="caster_wheel_joint" type="fixed">
        <parent link="chassis"/>
        <child link="caster_wheel"/>
        <origin xyz ="0.28 0 0"/>
    </joint>
    <link name="caster_wheel">
        <visual>
            <geometry>
                <sphere radius="0.05"/>
            </geometry>
            <material name="orange"/>
        </visual>
        <collision>
            <geometry>
                <sphere radius="0.05"/>
            </geometry>
        </collision>
    </link>




</robot>